---
layout: article
title: 【Node.js】promiseの使い方まとめ
tags: Node.js
aside:
  toc: true
---
Promiseの使い方のまとめ

参考サイトを読んでPromiseを理解する

- [JavaScript Promiseの本](https://azu.github.io/promises-book/#chapter1-what-is-promise)


## Promiseとは

>Promiseは非同期処理を抽象化したオブジェクトとそれを操作する仕組みのこと


## なぜ必要なのか
DBから値を取得したり、APIの実行結果を取得する際に、JavaScriptやNodeでは「取得した結果」を受け取る前に次の処理に進んでしまう(非同期実行されてしまう)。

例えば以下の処理では
```js

const getUsers = ()=> {
  this.connection.query('SELECT * FROM users',(err,rows)=>{
  return rows;
});

console.log(checkRoomStatus())
// undefined

```
DBに値があっても、このコードの実行結果は`undefined`になる。
取得結果を取得する前に、「取得する」という処理がおわり、「取得結果を表示」しようとしているから。

<br />
<br />
ではどうすればいいのか。<br />
「結果を受け取ってから次の処理に進む」ようにすればいい。<br />
それを実現するのに便利なのがPromise。

```js
const getUsers = ()=> {
  return new Promise((resolve) => {
      this.connection.query('SELECT * FROM users',(err,rows)=>{
        resolve(rows)
    });
});

getUsers().then((rows) => {
    console.log(rows);
    // SELECT実行結果が表示されるs
})
```

`getUsers()` の戻り値をPromiseインスタンスにし、呼び出す際には`.then()`を使うことで中身を取り出せる


## Promiseの状態
Promiseは実行結果取得まで待ってくれる仕組み。
3つの状態がある。

- Pending ・・・まだ処理を実行中の状態
- Fulfilled ・・・実行が成功し、値を取得したあとの状態
- Rejected ・・・何らかのエラーで処理が中断したあとの状態

![image](https://user-images.githubusercontent.com/44778704/103451460-aac3ca80-4d07-11eb-8480-322e256ddddc.png)


## 成功と失敗

Promise処理が成功した場合と失敗した場合とで処理の書き方を分ける必要がある。

- 成功した場合の処理・・・`.then()`で囲う
- 失敗した場合の処理・・・ `.catch()`で拾う

Promiseの処理は常に try-catch されているようなものなので、 例外が起きた場合もキャッチして、catch で登録された onRejected の処理を呼ぶ。
どちらの場合も、その後に実行したい関数を記載する。

```js
const fetch = require('node-fetch');
fetch("https://httpbin.org/status/500")
.then(function onFulfilled(value){
    console.log(value);
}).catch(function onRejected(error){
    console.error(error);
});
```
実行した関数は無名関数でもOK

```js
const fetch = require('node-fetch');
fetch("https://httpbin.org/status/500")
.then((value)=>{
    console.log(value);
}).catch( (error)=>{
    console.error(error);
});
```

別の書き方として、`.then()`で成功した結果と失敗した結果を両方受けとる関数を実行する方法もある。

```js
fetchURL(URL).then(onFulfilled, onRejected);
```

## promise chain

Promiseはメソッドチェーンでつなげることができる。

```js
const doTask = () => {
  return new Promise((resolve, reject) => {
    setTimeout(() => {
      console.log('1秒');
      resolve();
    }, 1000);
  });
};

promise
  .then(doTask)
  .then(doTask)
  .then(doTask);

// 1秒
// 1秒
// 1秒

```


以下のような書き方も可能。

```js
function taskA() {
    console.log("Task A");
}
function taskB() {
    console.log("Task B");
}
function onRejected(error) {
    console.log("Catch Error: A or B", error);
}
function finalTask() {
    console.log("Final Task");
}

const promise = Promise.resolve();
promise
    .then(taskA)
    .then(taskB)
    .catch(onRejected)
    .then(finalTask);
```

![image](https://user-images.githubusercontent.com/44778704/103451841-4a835780-4d0c-11eb-9d51-0f8668b58d1f.png)


上記の場合、TaskAでもTaskBでも何らかのエラーが起こった場合は`.catch()`に処理が移る。
TaskAで例外が起こった場合、TaskBは**実行されない**。


### 補足: Promise.resolve()とは

Promise.resolveは以下のコードのシュガーシンタックス。promiseインスタンスを生成している。

```js
const promise = new Promise((resolve) => {
  resolve();
});
```
### TaskAからTaskBに値を渡したい場合

returnすればよい

```js
function doubleUp(value) {
    return value * 2;
}
function increment(value) {
    return value + 1;
}
function output(value) {
    console.log(value);// => (1 + 1) * 2
}

const promise = Promise.resolve(1);
promise
    .then(increment)
    .then(doubleUp)
    .then(output)
    .catch((error) => {
        // promise chain中にエラーが発生した場合に呼ばれる
        console.error(error);
    });
```

`.then()`で明示的に値を渡さなくても、前処理の実行結果が渡っている。
非同期処理で値を渡す例は以下の通り。

```js

const promise2 = Promise.resolve(1000);
promise2
  .then((value) => {
    return new Promise((resolve, reject) => {
      setTimeout(() => {
        value += 1000;
        console.log(value);
        resolve(value);
      }, value);
    });
  })
  .then((value) => {
    return new Promise((resolve, reject) => {
      setTimeout(() => {
        value += 1000;
        console.log(value);
        resolve(value);
      }, value);
    });
  })
  .then((value) => {
    return new Promise((resolve, reject) => {
      setTimeout(() => {
        value += 1000;
        console.log(value);
        resolve(value);
      }, value);
    });
  });
```

## 実はfinallyもある

成功しても失敗しても実行したい処理があれば、`finally` で定義が可能

```js
function onFinally() {
    // 成功、失敗どちらでも実行したい処理
}

// `Promise#finally` は新しいpromiseオブジェクトを返す
Promise.resolve(42)
    .finally(onFinally)
    .then((value) => {
        // 呼び出し元のpromiseオブジェクトの状態をそのまま引き継ぐ
        // 呼び出し元のpromiseオブジェクトは `42` で resolveされている
        console.log(value); // 42
    });
```


## Promise.all

一つずつ順次promiseを実行するのではなく、複数の関数を同時に実行し、すべての処理が完了してから次の処理を行いたい時には`Promise.all()`が便利。


```js
Promise.all([関数1, 関数2, 関数3...])
  .then(values=>{
    // すべての関数の結果取得後に実行したい処理
    // valuesには各関数の実行結果が配列で格納されている
})

```

使用例:

```js
const timerPromisefy = (delay) => {
  return new Promise((resolve) => {
    setTimeout(() => {
      console.log(delay);
      resolve(delay);
    }, delay);
  });
};
const startDate = Date.now();
// 全てがresolveされたら終了
Promise.all([
  timerPromisefy(1000),
  timerPromisefy(1300),
  timerPromisefy(1600),
  timerPromisefy(1900),
]).then((values) => {
  console.log(Date.now() - startDate + 'ms'); // 約1907ms
  console.log(values); // [ 1000, 1300, 1600, 1900 ]
});
```


以上
